aasd = {
    "03c195c7-b078-4483-9256-dff3260a93d8": {
        "uuid": "03c195c7-b078-4483-9256-dff3260a93d8",
        "name": "run_inference_pipeline",
        "state": "FAILURE",
        "received": 1695200379.4563117,
        "sent": null,
        "started": 1695200379.4584556,
        "rejected": null,
        "succeeded": null,
        "failed": 1695200379.4802837,
        "retried": null,
        "revoked": null,
        "args": "(['/usr/src/app/vol_mount/2.wav', '/usr/src/app/vol_mount/a.wav', '/usr/src/app/vol_mount/1.wav'], 'sincnet-v1')",
        "kwargs": "{}",
        "eta": null,
        "expires": null,
        "retries": 0,
        "result": null,
        "exception": "NameError(\"name 'received_time' is not defined\")",
        "timestamp": 1695200379.4802837,
        "runtime": null,
        "traceback": 'Traceback (most recent call last):\n  File "/usr/local/lib/python3.8/site-packages/celery/app/trace.py", line 451, in trace_task\n    R = retval = fun(*args, **kwargs)\n  File "/usr/local/lib/python3.8/site-packages/celery/app/trace.py", line 734, in __protected_call__\n    return self.run(*args, **kwargs)\n  File "/usr/src/app/src/klass/vad_fastapi/worker.py", line 55, in run_inference_pipeline\n    logger.info("RECEIVED TIME: %s", received_time)\nNameError: name \'received_time\' is not defined\n',
        "exchange": null,
        "routing_key": null,
        "clock": 7,
        "client": null,
        "root": "03c195c7-b078-4483-9256-dff3260a93d8",
        "root_id": "03c195c7-b078-4483-9256-dff3260a93d8",
        "parent": null,
        "parent_id": null,
        "children": [],
        "worker": "celery@dd6ad65ec30e",
    },
    "2eb62ec5-dc55-40a5-966f-a10b66bb3027": {
        "uuid": "2eb62ec5-dc55-40a5-966f-a10b66bb3027",
        "name": "run_inference_pipeline",
        "state": "FAILURE",
        "received": 1695200296.7614648,
        "sent": null,
        "started": 1695200296.763048,
        "rejected": null,
        "succeeded": null,
        "failed": 1695200296.7798383,
        "retried": null,
        "revoked": null,
        "args": "(['/usr/src/app/vol_mount/2.wav', '/usr/src/app/vol_mount/a.wav', '/usr/src/app/vol_mount/1.wav'], 'sincnet-v1')",
        "kwargs": "{}",
        "eta": null,
        "expires": null,
        "retries": 0,
        "result": null,
        "exception": "AttributeError(\"'Context' object has no attribute 'received_time'\")",
        "timestamp": 1695200296.7798383,
        "runtime": null,
        "traceback": 'Traceback (most recent call last):\n  File "/usr/local/lib/python3.8/site-packages/celery/app/trace.py", line 451, in trace_task\n    R = retval = fun(*args, **kwargs)\n  File "/usr/local/lib/python3.8/site-packages/celery/app/trace.py", line 734, in __protected_call__\n    return self.run(*args, **kwargs)\n  File "/usr/src/app/src/klass/vad_fastapi/worker.py", line 51, in run_inference_pipeline\n    received_time = run_inference_pipeline.request.received_time\nAttributeError: \'Context\' object has no attribute \'received_time\'\n',
        "exchange": null,
        "routing_key": null,
        "clock": 104,
        "client": null,
        "root": "2eb62ec5-dc55-40a5-966f-a10b66bb3027",
        "root_id": "2eb62ec5-dc55-40a5-966f-a10b66bb3027",
        "parent": null,
        "parent_id": null,
        "children": [],
        "worker": "celery@348b9453ed75",
    },
    "597df053-cdc4-4fc7-a318-977200a67030": {
        "uuid": "597df053-cdc4-4fc7-a318-977200a67030",
        "name": "run_inference_pipeline",
        "state": "FAILURE",
        "received": 1695199729.1409268,
        "sent": null,
        "started": 1695199729.1425107,
        "rejected": null,
        "succeeded": null,
        "failed": 1695199729.1718936,
        "retried": null,
        "revoked": null,
        "args": "(['/usr/src/app/vol_mount/2.wav', '/usr/src/app/vol_mount/a.wav', '/usr/src/app/vol_mount/1.wav'], 'sincnet-v1')",
        "kwargs": "{}",
        "eta": null,
        "expires": null,
        "retries": 0,
        "result": null,
        "exception": "NameError(\"name 'my_task' is not defined\")",
        "timestamp": 1695199729.1718936,
        "runtime": null,
        "traceback": 'Traceback (most recent call last):\n  File "/usr/local/lib/python3.8/site-packages/celery/app/trace.py", line 451, in trace_task\n    R = retval = fun(*args, **kwargs)\n  File "/usr/local/lib/python3.8/site-packages/celery/app/trace.py", line 734, in __protected_call__\n    return self.run(*args, **kwargs)\n  File "/usr/src/app/src/klass/vad_fastapi/worker.py", line 63, in run_inference_pipeline\n    received_time = self.request.headers.get("received_time")\nNameError: name \'my_task\' is not defined\n',
        "exchange": null,
        "routing_key": null,
        "clock": 123,
        "client": null,
        "root": "597df053-cdc4-4fc7-a318-977200a67030",
        "root_id": "597df053-cdc4-4fc7-a318-977200a67030",
        "parent": null,
        "parent_id": null,
        "children": [],
        "worker": "celery@a94a847c52f2",
    },
    "f62c673c-eb60-4580-ac61-007c42f162a6": {
        "uuid": "f62c673c-eb60-4580-ac61-007c42f162a6",
        "name": "run_inference_pipeline",
        "state": "FAILURE",
        "received": 1695199648.5974493,
        "sent": null,
        "started": 1695199648.6001093,
        "rejected": null,
        "succeeded": null,
        "failed": 1695199648.621516,
        "retried": null,
        "revoked": null,
        "args": "(['/usr/src/app/vol_mount/2.wav', '/usr/src/app/vol_mount/a.wav', '/usr/src/app/vol_mount/1.wav'], 'sincnet-v1')",
        "kwargs": "{}",
        "eta": null,
        "expires": null,
        "retries": 0,
        "result": null,
        "exception": "NameError(\"name 'my_task' is not defined\")",
        "timestamp": 1695199648.621516,
        "runtime": null,
        "traceback": 'Traceback (most recent call last):\n  File "/usr/local/lib/python3.8/site-packages/celery/app/trace.py", line 451, in trace_task\n    R = retval = fun(*args, **kwargs)\n  File "/usr/local/lib/python3.8/site-packages/celery/app/trace.py", line 734, in __protected_call__\n    return self.run(*args, **kwargs)\n  File "/usr/src/app/src/klass/vad_fastapi/worker.py", line 63, in run_inference_pipeline\n    received_time = my_task.request.headers.get("received_time")\nNameError: name \'my_task\' is not defined\n',
        "exchange": null,
        "routing_key": null,
        "clock": 24,
        "client": null,
        "root": "f62c673c-eb60-4580-ac61-007c42f162a6",
        "root_id": "f62c673c-eb60-4580-ac61-007c42f162a6",
        "parent": null,
        "parent_id": null,
        "children": [],
        "worker": "celery@a94a847c52f2",
    },
    "56818f0e-320e-472d-a34c-82363695ff84": {
        "uuid": "56818f0e-320e-472d-a34c-82363695ff84",
        "name": "run_inference_pipeline",
        "state": "SUCCESS",
        "received": 1695198918.1571124,
        "sent": null,
        "started": 1695198918.1591563,
        "rejected": null,
        "succeeded": 1695198934.2322142,
        "failed": null,
        "retried": null,
        "revoked": null,
        "args": "(['/usr/src/app/vol_mount/2.wav', '/usr/src/app/vol_mount/a.wav', '/usr/src/app/vol_mount/1.wav'], 'sincnet-v1')",
        "kwargs": "{}",
        "eta": null,
        "expires": null,
        "retries": 0,
        "result": "{'/usr/src/app/vol_mount/2.wav': {'status': 'ERROR: File not found', 'rttm_path': None}, '/usr/src/app/vol_mount/a.wav': {'status': 'SUCCESS', 'rttm_path': '/usr/src/app/vol_mount/output_rttm/a.rttm'}, '/usr/src/app/vol_mount/1.wav': {'status': 'ERROR: Error during model inference', 'rttm_path': None}}",
        "exception": null,
        "timestamp": 1695198934.2322142,
        "runtime": 16.072262848996616,
        "traceback": null,
        "exchange": null,
        "routing_key": null,
        "clock": 75,
        "client": null,
        "root": "56818f0e-320e-472d-a34c-82363695ff84",
        "root_id": "56818f0e-320e-472d-a34c-82363695ff84",
        "parent": null,
        "parent_id": null,
        "children": [],
        "worker": "celery@0d146fc19b35",
    },
    "09312741-b90e-4f44-9916-af9c1b171cc5": {
        "uuid": "09312741-b90e-4f44-9916-af9c1b171cc5",
        "name": null,
        "state": "FAILURE",
        "received": null,
        "sent": null,
        "started": 1695199807.0456724,
        "rejected": null,
        "succeeded": null,
        "failed": 1695199807.0586498,
        "retried": null,
        "revoked": null,
        "args": null,
        "kwargs": null,
        "eta": null,
        "expires": null,
        "retries": null,
        "result": null,
        "exception": "AttributeError(\"'NoneType' object has no attribute 'get'\")",
        "timestamp": 1695199807.0586498,
        "runtime": null,
        "traceback": 'Traceback (most recent call last):\n  File "/usr/local/lib/python3.8/site-packages/celery/app/trace.py", line 451, in trace_task\n    R = retval = fun(*args, **kwargs)\n  File "/usr/local/lib/python3.8/site-packages/celery/app/trace.py", line 734, in __protected_call__\n    return self.run(*args, **kwargs)\n  File "/usr/src/app/src/klass/vad_fastapi/worker.py", line 63, in run_inference_pipeline\n    received_time = self.request.headers.get("received_time")\nAttributeError: \'NoneType\' object has no attribute \'get\'\n',
        "exchange": null,
        "routing_key": null,
        "clock": 5,
        "client": null,
        "root": null,
        "root_id": null,
        "parent": null,
        "parent_id": null,
        "children": [],
        "worker": "celery@0e8766d7d7c6",
    },
}
